3/27/2020 12:13:29 PM{"timestamp": "2020-03-27T19:13:29.312474Z", "level": "DEBUG", "name": "root", "message": "Redirecting user for auth_token", "container": "46b95b1cfc43", "type": "narrative-traefiker", "auth_redirect": "https://ci.kbase.us/#login?nextrequest={\"path\":\"{}\",\"external\":true}", "request.url": "http://logstashanl.chicago.kbase.us/narrative/ws.12202.obj.1"}
3/27/2020 12:13:29 PM{"asctime": "2020-03-27T19:13:29+0000", "name": "app", "levelname": "ERROR", "message": "Exception on /narrative/ws.12202.obj.1 [GET]", "exc_info": "Traceback (most recent call last):\n  File \"/usr/local/lib/python3.6/site-packages/flask/app.py\", line 2446, in wsgi_app\n    response = self.full_dispatch_request()\n  File \"/usr/local/lib/python3.6/site-packages/flask/app.py\", line 1951, in full_dispatch_request\n    rv = self.handle_user_exception(e)\n  File \"/usr/local/lib/python3.6/site-packages/flask/app.py\", line 1820, in handle_user_exception\n    reraise(exc_type, exc_value, tb)\n  File \"/usr/local/lib/python3.6/site-packages/flask/_compat.py\", line 39, in reraise\n    raise value\n  File \"/usr/local/lib/python3.6/site-packages/flask/app.py\", line 1949, in full_dispatch_request\n    rv = self.dispatch_request()\n  File \"/usr/local/lib/python3.6/site-packages/flask/app.py\", line 1935, in dispatch_request\n    return self.view_functions[rule.endpoint](**req.view_args)\n  File \"/app/app.py\", line 401, in hello\n    resp = auth_redirect(cfg['auth_redirect'].format(request.url))\nKeyError: '\"path\"'"}
